<?xml version="1.0" encoding="UTF-8"?>
<testsuite name="Run On Chrome"
           tests="2"
           failures="2"
           errors="0"
           skipped="0"
           time="5.150">
    <properties></properties>

            <testcase
                name="Login_02_Login"
                time="1.999"
                classname="testcases.user.Level_14_Log_ReportNG">

            <failure type="java.lang.Throwable" message="Multiple failures (2):
Failure 1 of 2
java.lang.AssertionError: expected [false] but found [true]
	at org.testng.Assert.fail(Assert.java:97)
	at org.testng.Assert.failNotEquals(Assert.java:969)
	at org.testng.Assert.assertFalse(Assert.java:65)
	at org.testng.Assert.assertFalse(Assert.java:75)
	at actions.commons.BaseTest.verifyFalse(BaseTest.java:122)
	at testcases.user.Level_14_Log_ReportNG.Login_02_Login(Level_14_Log_ReportNG.java:80)
	at java.base/jdk.internal.reflect.NativeMethodAccessorImpl.invoke0(Native Method)
	at java.base/jdk.internal.reflect.NativeMethodAccessorImpl.invoke(NativeMethodAccessorImpl.java:77)
	at java.base/jdk.internal.reflect.DelegatingMethodAccessorImpl.invoke(DelegatingMethodAccessorImpl.java:43)
	at java.base/java.lang.reflect.Method.invoke(Method.java:568)
	at org.testng.internal.MethodInvocationHelper.invokeMethod(MethodInvocationHelper.java:134)
	at org.testng.internal.TestInvoker.invokeMethod(TestInvoker.java:597)
	at org.testng.internal.TestInvoker.invokeTestMethod(TestInvoker.java:173)
	at org.testng.internal.MethodRunner.runInSequence(MethodRunner.java:46)
	at org.testng.internal.TestInvoker$MethodInvocationAgent.invoke(TestInvoker.java:816)
	at org.testng.internal.TestInvoker.invokeTestMethods(TestInvoker.java:146)
	at org.testng.internal.TestMethodWorker.invokeTestMethods(TestMethodWorker.java:146)
	at org.testng.internal.TestMethodWorker.run(TestMethodWorker.java:128)
	at java.base/java.util.ArrayList.forEach(ArrayList.java:1511)
	at org.testng.TestRunner.privateRun(TestRunner.java:766)
	at org.testng.TestRunner.run(TestRunner.java:587)
	at org.testng.SuiteRunner.runTest(SuiteRunner.java:384)
	at org.testng.SuiteRunner.runSequentially(SuiteRunner.java:378)
	at org.testng.SuiteRunner.privateRun(SuiteRunner.java:337)
	at org.testng.SuiteRunner.run(SuiteRunner.java:286)
	at org.testng.SuiteRunnerWorker.runSuite(SuiteRunnerWorker.java:53)
	at org.testng.SuiteRunnerWorker.run(SuiteRunnerWorker.java:96)
	at org.testng.TestNG.runSuitesSequentially(TestNG.java:1187)
	at org.testng.TestNG.runSuitesLocally(TestNG.java:1109)
	at org.testng.TestNG.runSuites(TestNG.java:1039)
	at org.testng.TestNG.run(TestNG.java:1007)
	at com.intellij.rt.testng.IDEARemoteTestNG.run(IDEARemoteTestNG.java:66)
	at com.intellij.rt.testng.RemoteTestNGStarter.main(RemoteTestNGStarter.java:105)

Failure 2 of 2
java.lang.AssertionError: expected [false] but found [true]">
                <![CDATA[java.lang.Throwable: Multiple failures (2):
Failure 1 of 2
java.lang.AssertionError: expected [false] but found [true]
	at org.testng.Assert.fail(Assert.java:97)
	at org.testng.Assert.failNotEquals(Assert.java:969)
	at org.testng.Assert.assertFalse(Assert.java:65)
	at org.testng.Assert.assertFalse(Assert.java:75)
	at actions.commons.BaseTest.verifyFalse(BaseTest.java:122)
	at testcases.user.Level_14_Log_ReportNG.Login_02_Login(Level_14_Log_ReportNG.java:80)
	at java.base/jdk.internal.reflect.NativeMethodAccessorImpl.invoke0(Native Method)
	at java.base/jdk.internal.reflect.NativeMethodAccessorImpl.invoke(NativeMethodAccessorImpl.java:77)
	at java.base/jdk.internal.reflect.DelegatingMethodAccessorImpl.invoke(DelegatingMethodAccessorImpl.java:43)
	at java.base/java.lang.reflect.Method.invoke(Method.java:568)
	at org.testng.internal.MethodInvocationHelper.invokeMethod(MethodInvocationHelper.java:134)
	at org.testng.internal.TestInvoker.invokeMethod(TestInvoker.java:597)
	at org.testng.internal.TestInvoker.invokeTestMethod(TestInvoker.java:173)
	at org.testng.internal.MethodRunner.runInSequence(MethodRunner.java:46)
	at org.testng.internal.TestInvoker$MethodInvocationAgent.invoke(TestInvoker.java:816)
	at org.testng.internal.TestInvoker.invokeTestMethods(TestInvoker.java:146)
	at org.testng.internal.TestMethodWorker.invokeTestMethods(TestMethodWorker.java:146)
	at org.testng.internal.TestMethodWorker.run(TestMethodWorker.java:128)
	at java.base/java.util.ArrayList.forEach(ArrayList.java:1511)
	at org.testng.TestRunner.privateRun(TestRunner.java:766)
	at org.testng.TestRunner.run(TestRunner.java:587)
	at org.testng.SuiteRunner.runTest(SuiteRunner.java:384)
	at org.testng.SuiteRunner.runSequentially(SuiteRunner.java:378)
	at org.testng.SuiteRunner.privateRun(SuiteRunner.java:337)
	at org.testng.SuiteRunner.run(SuiteRunner.java:286)
	at org.testng.SuiteRunnerWorker.runSuite(SuiteRunnerWorker.java:53)
	at org.testng.SuiteRunnerWorker.run(SuiteRunnerWorker.java:96)
	at org.testng.TestNG.runSuitesSequentially(TestNG.java:1187)
	at org.testng.TestNG.runSuitesLocally(TestNG.java:1109)
	at org.testng.TestNG.runSuites(TestNG.java:1039)
	at org.testng.TestNG.run(TestNG.java:1007)
	at com.intellij.rt.testng.IDEARemoteTestNG.run(IDEARemoteTestNG.java:66)
	at com.intellij.rt.testng.RemoteTestNGStarter.main(RemoteTestNGStarter.java:105)

Failure 2 of 2
java.lang.AssertionError: expected [false] but found [true]
                org.testng.Assert.fail(Assert.java:97)org.testng.Assert.failNotEquals(Assert.java:969)org.testng.Assert.assertFalse(Assert.java:65)org.testng.Assert.assertFalse(Assert.java:75)actions.commons.BaseTest.verifyFalse(BaseTest.java:122)testcases.user.Level_14_Log_ReportNG.Login_02_Login(Level_14_Log_ReportNG.java:84)java.base/jdk.internal.reflect.NativeMethodAccessorImpl.invoke0(Native Method)java.base/jdk.internal.reflect.NativeMethodAccessorImpl.invoke(NativeMethodAccessorImpl.java:77)java.base/jdk.internal.reflect.DelegatingMethodAccessorImpl.invoke(DelegatingMethodAccessorImpl.java:43)java.base/java.lang.reflect.Method.invoke(Method.java:568)org.testng.internal.MethodInvocationHelper.invokeMethod(MethodInvocationHelper.java:134)org.testng.internal.TestInvoker.invokeMethod(TestInvoker.java:597)org.testng.internal.TestInvoker.invokeTestMethod(TestInvoker.java:173)org.testng.internal.MethodRunner.runInSequence(MethodRunner.java:46)org.testng.internal.TestInvoker$MethodInvocationAgent.invoke(TestInvoker.java:816)org.testng.internal.TestInvoker.invokeTestMethods(TestInvoker.java:146)org.testng.internal.TestMethodWorker.invokeTestMethods(TestMethodWorker.java:146)org.testng.internal.TestMethodWorker.run(TestMethodWorker.java:128)java.base/java.util.ArrayList.forEach(ArrayList.java:1511)org.testng.TestRunner.privateRun(TestRunner.java:766)org.testng.TestRunner.run(TestRunner.java:587)org.testng.SuiteRunner.runTest(SuiteRunner.java:384)org.testng.SuiteRunner.runSequentially(SuiteRunner.java:378)org.testng.SuiteRunner.privateRun(SuiteRunner.java:337)org.testng.SuiteRunner.run(SuiteRunner.java:286)org.testng.SuiteRunnerWorker.runSuite(SuiteRunnerWorker.java:53)org.testng.SuiteRunnerWorker.run(SuiteRunnerWorker.java:96)org.testng.TestNG.runSuitesSequentially(TestNG.java:1187)org.testng.TestNG.runSuitesLocally(TestNG.java:1109)org.testng.TestNG.runSuites(TestNG.java:1039)org.testng.TestNG.run(TestNG.java:1007)com.intellij.rt.testng.IDEARemoteTestNG.run(IDEARemoteTestNG.java:66)com.intellij.rt.testng.RemoteTestNGStarter.main(RemoteTestNGStarter.java:105)
]]>
            </failure>
    </testcase>
            <testcase
                name="Login_01_Register_Login_My_Account"
                time="3.151"
                classname="testcases.user.Level_14_Log_ReportNG">

            <failure type="java.lang.AssertionError" message="expected [Your registration completed..] but found [Your registration completed]">
                <![CDATA[java.lang.AssertionError: expected [Your registration completed..] but found [Your registration completed]
                org.testng.Assert.fail(Assert.java:97)org.testng.Assert.assertEqualsImpl(Assert.java:136)org.testng.Assert.assertEquals(Assert.java:118)org.testng.Assert.assertEquals(Assert.java:563)actions.commons.BaseTest.verifyEquals(BaseTest.java:137)testcases.user.Level_14_Log_ReportNG.Login_01_Register_Login_My_Account(Level_14_Log_ReportNG.java:59)java.base/jdk.internal.reflect.NativeMethodAccessorImpl.invoke0(Native Method)java.base/jdk.internal.reflect.NativeMethodAccessorImpl.invoke(NativeMethodAccessorImpl.java:77)java.base/jdk.internal.reflect.DelegatingMethodAccessorImpl.invoke(DelegatingMethodAccessorImpl.java:43)java.base/java.lang.reflect.Method.invoke(Method.java:568)org.testng.internal.MethodInvocationHelper.invokeMethod(MethodInvocationHelper.java:134)org.testng.internal.TestInvoker.invokeMethod(TestInvoker.java:597)org.testng.internal.TestInvoker.invokeTestMethod(TestInvoker.java:173)org.testng.internal.MethodRunner.runInSequence(MethodRunner.java:46)org.testng.internal.TestInvoker$MethodInvocationAgent.invoke(TestInvoker.java:816)org.testng.internal.TestInvoker.invokeTestMethods(TestInvoker.java:146)org.testng.internal.TestMethodWorker.invokeTestMethods(TestMethodWorker.java:146)org.testng.internal.TestMethodWorker.run(TestMethodWorker.java:128)java.base/java.util.ArrayList.forEach(ArrayList.java:1511)org.testng.TestRunner.privateRun(TestRunner.java:766)org.testng.TestRunner.run(TestRunner.java:587)org.testng.SuiteRunner.runTest(SuiteRunner.java:384)org.testng.SuiteRunner.runSequentially(SuiteRunner.java:378)org.testng.SuiteRunner.privateRun(SuiteRunner.java:337)org.testng.SuiteRunner.run(SuiteRunner.java:286)org.testng.SuiteRunnerWorker.runSuite(SuiteRunnerWorker.java:53)org.testng.SuiteRunnerWorker.run(SuiteRunnerWorker.java:96)org.testng.TestNG.runSuitesSequentially(TestNG.java:1187)org.testng.TestNG.runSuitesLocally(TestNG.java:1109)org.testng.TestNG.runSuites(TestNG.java:1039)org.testng.TestNG.run(TestNG.java:1007)com.intellij.rt.testng.IDEARemoteTestNG.run(IDEARemoteTestNG.java:66)com.intellij.rt.testng.RemoteTestNGStarter.main(RemoteTestNGStarter.java:105)
]]>
            </failure>
    </testcase>


</testsuite>
